Traceback (most recent call last):
  File "/opt/hostedtoolcache/Python/3.9.12/x64/lib/python3.9/site-packages/jupyter_cache/executors/utils.py", line 51, in single_nb_execution
    executenb(
  File "/opt/hostedtoolcache/Python/3.9.12/x64/lib/python3.9/site-packages/nbclient/client.py", line 1204, in execute
    return NotebookClient(nb=nb, resources=resources, km=km, **kwargs).execute()
  File "/opt/hostedtoolcache/Python/3.9.12/x64/lib/python3.9/site-packages/nbclient/util.py", line 84, in wrapped
    return just_run(coro(*args, **kwargs))
  File "/opt/hostedtoolcache/Python/3.9.12/x64/lib/python3.9/site-packages/nbclient/util.py", line 62, in just_run
    return loop.run_until_complete(coro)
  File "/opt/hostedtoolcache/Python/3.9.12/x64/lib/python3.9/asyncio/base_events.py", line 647, in run_until_complete
    return future.result()
  File "/opt/hostedtoolcache/Python/3.9.12/x64/lib/python3.9/site-packages/nbclient/client.py", line 663, in async_execute
    await self.async_execute_cell(
  File "/opt/hostedtoolcache/Python/3.9.12/x64/lib/python3.9/site-packages/nbclient/client.py", line 965, in async_execute_cell
    await self._check_raise_for_error(cell, cell_index, exec_reply)
  File "/opt/hostedtoolcache/Python/3.9.12/x64/lib/python3.9/site-packages/nbclient/client.py", line 862, in _check_raise_for_error
    raise CellExecutionError.from_cell_and_msg(cell, exec_reply_content)
nbclient.exceptions.CellExecutionError: An error occurred while executing the following cell:
------------------
import json
import uuid
from confluent_kafka import Producer
from ksql import KSQLAPI
bootstrap_servers='[::1]:9092'
topic='stats0101'
msg_count=5
client = KSQLAPI(url='http://localhost:8088', timeout=60000)
------------------

[0;31m---------------------------------------------------------------------------[0m
[0;31mConnectionRefusedError[0m                    Traceback (most recent call last)
File [0;32m/opt/hostedtoolcache/Python/3.9.12/x64/lib/python3.9/site-packages/urllib3/connection.py:174[0m, in [0;36mHTTPConnection._new_conn[0;34m(self)[0m
[1;32m    173[0m [38;5;28;01mtry[39;00m:
[0;32m--> 174[0m     conn [38;5;241m=[39m [43mconnection[49m[38;5;241;43m.[39;49m[43mcreate_connection[49m[43m([49m
[1;32m    175[0m [43m        [49m[43m([49m[38;5;28;43mself[39;49m[38;5;241;43m.[39;49m[43m_dns_host[49m[43m,[49m[43m [49m[38;5;28;43mself[39;49m[38;5;241;43m.[39;49m[43mport[49m[43m)[49m[43m,[49m[43m [49m[38;5;28;43mself[39;49m[38;5;241;43m.[39;49m[43mtimeout[49m[43m,[49m[43m [49m[38;5;241;43m*[39;49m[38;5;241;43m*[39;49m[43mextra_kw[49m
[1;32m    176[0m [43m    [49m[43m)[49m
[1;32m    178[0m [38;5;28;01mexcept[39;00m SocketTimeout:

File [0;32m/opt/hostedtoolcache/Python/3.9.12/x64/lib/python3.9/site-packages/urllib3/util/connection.py:95[0m, in [0;36mcreate_connection[0;34m(address, timeout, source_address, socket_options)[0m
[1;32m     94[0m [38;5;28;01mif[39;00m err [38;5;129;01mis[39;00m [38;5;129;01mnot[39;00m [38;5;28;01mNone[39;00m:
[0;32m---> 95[0m     [38;5;28;01mraise[39;00m err
[1;32m     97[0m [38;5;28;01mraise[39;00m socket[38;5;241m.[39merror([38;5;124m"[39m[38;5;124mgetaddrinfo returns an empty list[39m[38;5;124m"[39m)

File [0;32m/opt/hostedtoolcache/Python/3.9.12/x64/lib/python3.9/site-packages/urllib3/util/connection.py:85[0m, in [0;36mcreate_connection[0;34m(address, timeout, source_address, socket_options)[0m
[1;32m     84[0m     sock[38;5;241m.[39mbind(source_address)
[0;32m---> 85[0m [43msock[49m[38;5;241;43m.[39;49m[43mconnect[49m[43m([49m[43msa[49m[43m)[49m
[1;32m     86[0m [38;5;28;01mreturn[39;00m sock

[0;31mConnectionRefusedError[0m: [Errno 111] Connection refused

During handling of the above exception, another exception occurred:

[0;31mNewConnectionError[0m                        Traceback (most recent call last)
File [0;32m/opt/hostedtoolcache/Python/3.9.12/x64/lib/python3.9/site-packages/urllib3/connectionpool.py:703[0m, in [0;36mHTTPConnectionPool.urlopen[0;34m(self, method, url, body, headers, retries, redirect, assert_same_host, timeout, pool_timeout, release_conn, chunked, body_pos, **response_kw)[0m
[1;32m    702[0m [38;5;66;03m# Make the request on the httplib connection object.[39;00m
[0;32m--> 703[0m httplib_response [38;5;241m=[39m [38;5;28;43mself[39;49m[38;5;241;43m.[39;49m[43m_make_request[49m[43m([49m
[1;32m    704[0m [43m    [49m[43mconn[49m[43m,[49m
[1;32m    705[0m [43m    [49m[43mmethod[49m[43m,[49m
[1;32m    706[0m [43m    [49m[43murl[49m[43m,[49m
[1;32m    707[0m [43m    [49m[43mtimeout[49m[38;5;241;43m=[39;49m[43mtimeout_obj[49m[43m,[49m
[1;32m    708[0m [43m    [49m[43mbody[49m[38;5;241;43m=[39;49m[43mbody[49m[43m,[49m
[1;32m    709[0m [43m    [49m[43mheaders[49m[38;5;241;43m=[39;49m[43mheaders[49m[43m,[49m
[1;32m    710[0m [43m    [49m[43mchunked[49m[38;5;241;43m=[39;49m[43mchunked[49m[43m,[49m
[1;32m    711[0m [43m[49m[43m)[49m
[1;32m    713[0m [38;5;66;03m# If we're going to release the connection in ``finally:``, then[39;00m
[1;32m    714[0m [38;5;66;03m# the response doesn't need to know about the connection. Otherwise[39;00m
[1;32m    715[0m [38;5;66;03m# it will also try to release it and we'll have a double-release[39;00m
[1;32m    716[0m [38;5;66;03m# mess.[39;00m

File [0;32m/opt/hostedtoolcache/Python/3.9.12/x64/lib/python3.9/site-packages/urllib3/connectionpool.py:398[0m, in [0;36mHTTPConnectionPool._make_request[0;34m(self, conn, method, url, timeout, chunked, **httplib_request_kw)[0m
[1;32m    397[0m     [38;5;28;01melse[39;00m:
[0;32m--> 398[0m         [43mconn[49m[38;5;241;43m.[39;49m[43mrequest[49m[43m([49m[43mmethod[49m[43m,[49m[43m [49m[43murl[49m[43m,[49m[43m [49m[38;5;241;43m*[39;49m[38;5;241;43m*[39;49m[43mhttplib_request_kw[49m[43m)[49m
[1;32m    400[0m [38;5;66;03m# We are swallowing BrokenPipeError (errno.EPIPE) since the server is[39;00m
[1;32m    401[0m [38;5;66;03m# legitimately able to close the connection after sending a valid response.[39;00m
[1;32m    402[0m [38;5;66;03m# With this behaviour, the received response is still readable.[39;00m

File [0;32m/opt/hostedtoolcache/Python/3.9.12/x64/lib/python3.9/site-packages/urllib3/connection.py:239[0m, in [0;36mHTTPConnection.request[0;34m(self, method, url, body, headers)[0m
[1;32m    238[0m     headers[[38;5;124m"[39m[38;5;124mUser-Agent[39m[38;5;124m"[39m] [38;5;241m=[39m _get_default_user_agent()
[0;32m--> 239[0m [38;5;28;43msuper[39;49m[43m([49m[43mHTTPConnection[49m[43m,[49m[43m [49m[38;5;28;43mself[39;49m[43m)[49m[38;5;241;43m.[39;49m[43mrequest[49m[43m([49m[43mmethod[49m[43m,[49m[43m [49m[43murl[49m[43m,[49m[43m [49m[43mbody[49m[38;5;241;43m=[39;49m[43mbody[49m[43m,[49m[43m [49m[43mheaders[49m[38;5;241;43m=[39;49m[43mheaders[49m[43m)[49m

File [0;32m/opt/hostedtoolcache/Python/3.9.12/x64/lib/python3.9/http/client.py:1285[0m, in [0;36mHTTPConnection.request[0;34m(self, method, url, body, headers, encode_chunked)[0m
[1;32m   1284[0m [38;5;124;03m"""Send a complete request to the server."""[39;00m
[0;32m-> 1285[0m [38;5;28;43mself[39;49m[38;5;241;43m.[39;49m[43m_send_request[49m[43m([49m[43mmethod[49m[43m,[49m[43m [49m[43murl[49m[43m,[49m[43m [49m[43mbody[49m[43m,[49m[43m [49m[43mheaders[49m[43m,[49m[43m [49m[43mencode_chunked[49m[43m)[49m

File [0;32m/opt/hostedtoolcache/Python/3.9.12/x64/lib/python3.9/http/client.py:1331[0m, in [0;36mHTTPConnection._send_request[0;34m(self, method, url, body, headers, encode_chunked)[0m
[1;32m   1330[0m     body [38;5;241m=[39m _encode(body, [38;5;124m'[39m[38;5;124mbody[39m[38;5;124m'[39m)
[0;32m-> 1331[0m [38;5;28;43mself[39;49m[38;5;241;43m.[39;49m[43mendheaders[49m[43m([49m[43mbody[49m[43m,[49m[43m [49m[43mencode_chunked[49m[38;5;241;43m=[39;49m[43mencode_chunked[49m[43m)[49m

File [0;32m/opt/hostedtoolcache/Python/3.9.12/x64/lib/python3.9/http/client.py:1280[0m, in [0;36mHTTPConnection.endheaders[0;34m(self, message_body, encode_chunked)[0m
[1;32m   1279[0m     [38;5;28;01mraise[39;00m CannotSendHeader()
[0;32m-> 1280[0m [38;5;28;43mself[39;49m[38;5;241;43m.[39;49m[43m_send_output[49m[43m([49m[43mmessage_body[49m[43m,[49m[43m [49m[43mencode_chunked[49m[38;5;241;43m=[39;49m[43mencode_chunked[49m[43m)[49m

File [0;32m/opt/hostedtoolcache/Python/3.9.12/x64/lib/python3.9/http/client.py:1040[0m, in [0;36mHTTPConnection._send_output[0;34m(self, message_body, encode_chunked)[0m
[1;32m   1039[0m [38;5;28;01mdel[39;00m [38;5;28mself[39m[38;5;241m.[39m_buffer[:]
[0;32m-> 1040[0m [38;5;28;43mself[39;49m[38;5;241;43m.[39;49m[43msend[49m[43m([49m[43mmsg[49m[43m)[49m
[1;32m   1042[0m [38;5;28;01mif[39;00m message_body [38;5;129;01mis[39;00m [38;5;129;01mnot[39;00m [38;5;28;01mNone[39;00m:
[1;32m   1043[0m 
[1;32m   1044[0m     [38;5;66;03m# create a consistent interface to message_body[39;00m

File [0;32m/opt/hostedtoolcache/Python/3.9.12/x64/lib/python3.9/http/client.py:980[0m, in [0;36mHTTPConnection.send[0;34m(self, data)[0m
[1;32m    979[0m [38;5;28;01mif[39;00m [38;5;28mself[39m[38;5;241m.[39mauto_open:
[0;32m--> 980[0m     [38;5;28;43mself[39;49m[38;5;241;43m.[39;49m[43mconnect[49m[43m([49m[43m)[49m
[1;32m    981[0m [38;5;28;01melse[39;00m:

File [0;32m/opt/hostedtoolcache/Python/3.9.12/x64/lib/python3.9/site-packages/urllib3/connection.py:205[0m, in [0;36mHTTPConnection.connect[0;34m(self)[0m
[1;32m    204[0m [38;5;28;01mdef[39;00m [38;5;21mconnect[39m([38;5;28mself[39m):
[0;32m--> 205[0m     conn [38;5;241m=[39m [38;5;28;43mself[39;49m[38;5;241;43m.[39;49m[43m_new_conn[49m[43m([49m[43m)[49m
[1;32m    206[0m     [38;5;28mself[39m[38;5;241m.[39m_prepare_conn(conn)

File [0;32m/opt/hostedtoolcache/Python/3.9.12/x64/lib/python3.9/site-packages/urllib3/connection.py:186[0m, in [0;36mHTTPConnection._new_conn[0;34m(self)[0m
[1;32m    185[0m [38;5;28;01mexcept[39;00m SocketError [38;5;28;01mas[39;00m e:
[0;32m--> 186[0m     [38;5;28;01mraise[39;00m NewConnectionError(
[1;32m    187[0m         [38;5;28mself[39m, [38;5;124m"[39m[38;5;124mFailed to establish a new connection: [39m[38;5;132;01m%s[39;00m[38;5;124m"[39m [38;5;241m%[39m e
[1;32m    188[0m     )
[1;32m    190[0m [38;5;28;01mreturn[39;00m conn

[0;31mNewConnectionError[0m: <urllib3.connection.HTTPConnection object at 0x7f78e0a1a400>: Failed to establish a new connection: [Errno 111] Connection refused

During handling of the above exception, another exception occurred:

[0;31mMaxRetryError[0m                             Traceback (most recent call last)
File [0;32m/opt/hostedtoolcache/Python/3.9.12/x64/lib/python3.9/site-packages/requests/adapters.py:440[0m, in [0;36mHTTPAdapter.send[0;34m(self, request, stream, timeout, verify, cert, proxies)[0m
[1;32m    439[0m [38;5;28;01mif[39;00m [38;5;129;01mnot[39;00m chunked:
[0;32m--> 440[0m     resp [38;5;241m=[39m [43mconn[49m[38;5;241;43m.[39;49m[43murlopen[49m[43m([49m
[1;32m    441[0m [43m        [49m[43mmethod[49m[38;5;241;43m=[39;49m[43mrequest[49m[38;5;241;43m.[39;49m[43mmethod[49m[43m,[49m
[1;32m    442[0m [43m        [49m[43murl[49m[38;5;241;43m=[39;49m[43murl[49m[43m,[49m
[1;32m    443[0m [43m        [49m[43mbody[49m[38;5;241;43m=[39;49m[43mrequest[49m[38;5;241;43m.[39;49m[43mbody[49m[43m,[49m
[1;32m    444[0m [43m        [49m[43mheaders[49m[38;5;241;43m=[39;49m[43mrequest[49m[38;5;241;43m.[39;49m[43mheaders[49m[43m,[49m
[1;32m    445[0m [43m        [49m[43mredirect[49m[38;5;241;43m=[39;49m[38;5;28;43;01mFalse[39;49;00m[43m,[49m
[1;32m    446[0m [43m        [49m[43massert_same_host[49m[38;5;241;43m=[39;49m[38;5;28;43;01mFalse[39;49;00m[43m,[49m
[1;32m    447[0m [43m        [49m[43mpreload_content[49m[38;5;241;43m=[39;49m[38;5;28;43;01mFalse[39;49;00m[43m,[49m
[1;32m    448[0m [43m        [49m[43mdecode_content[49m[38;5;241;43m=[39;49m[38;5;28;43;01mFalse[39;49;00m[43m,[49m
[1;32m    449[0m [43m        [49m[43mretries[49m[38;5;241;43m=[39;49m[38;5;28;43mself[39;49m[38;5;241;43m.[39;49m[43mmax_retries[49m[43m,[49m
[1;32m    450[0m [43m        [49m[43mtimeout[49m[38;5;241;43m=[39;49m[43mtimeout[49m
[1;32m    451[0m [43m    [49m[43m)[49m
[1;32m    453[0m [38;5;66;03m# Send the request.[39;00m
[1;32m    454[0m [38;5;28;01melse[39;00m:

File [0;32m/opt/hostedtoolcache/Python/3.9.12/x64/lib/python3.9/site-packages/urllib3/connectionpool.py:785[0m, in [0;36mHTTPConnectionPool.urlopen[0;34m(self, method, url, body, headers, retries, redirect, assert_same_host, timeout, pool_timeout, release_conn, chunked, body_pos, **response_kw)[0m
[1;32m    783[0m     e [38;5;241m=[39m ProtocolError([38;5;124m"[39m[38;5;124mConnection aborted.[39m[38;5;124m"[39m, e)
[0;32m--> 785[0m retries [38;5;241m=[39m [43mretries[49m[38;5;241;43m.[39;49m[43mincrement[49m[43m([49m
[1;32m    786[0m [43m    [49m[43mmethod[49m[43m,[49m[43m [49m[43murl[49m[43m,[49m[43m [49m[43merror[49m[38;5;241;43m=[39;49m[43me[49m[43m,[49m[43m [49m[43m_pool[49m[38;5;241;43m=[39;49m[38;5;28;43mself[39;49m[43m,[49m[43m [49m[43m_stacktrace[49m[38;5;241;43m=[39;49m[43msys[49m[38;5;241;43m.[39;49m[43mexc_info[49m[43m([49m[43m)[49m[43m[[49m[38;5;241;43m2[39;49m[43m][49m
[1;32m    787[0m [43m[49m[43m)[49m
[1;32m    788[0m retries[38;5;241m.[39msleep()

File [0;32m/opt/hostedtoolcache/Python/3.9.12/x64/lib/python3.9/site-packages/urllib3/util/retry.py:592[0m, in [0;36mRetry.increment[0;34m(self, method, url, response, error, _pool, _stacktrace)[0m
[1;32m    591[0m [38;5;28;01mif[39;00m new_retry[38;5;241m.[39mis_exhausted():
[0;32m--> 592[0m     [38;5;28;01mraise[39;00m MaxRetryError(_pool, url, error [38;5;129;01mor[39;00m ResponseError(cause))
[1;32m    594[0m log[38;5;241m.[39mdebug([38;5;124m"[39m[38;5;124mIncremented Retry for (url=[39m[38;5;124m'[39m[38;5;132;01m%s[39;00m[38;5;124m'[39m[38;5;124m): [39m[38;5;132;01m%r[39;00m[38;5;124m"[39m, url, new_retry)

[0;31mMaxRetryError[0m: HTTPConnectionPool(host='localhost', port=8088): Max retries exceeded with url: /info (Caused by NewConnectionError('<urllib3.connection.HTTPConnection object at 0x7f78e0a1a400>: Failed to establish a new connection: [Errno 111] Connection refused'))

During handling of the above exception, another exception occurred:

[0;31mConnectionError[0m                           Traceback (most recent call last)
Input [0;32mIn [3][0m, in [0;36m<cell line: 8>[0;34m()[0m
[1;32m      6[0m topic[38;5;241m=[39m[38;5;124m'[39m[38;5;124mstats0101[39m[38;5;124m'[39m
[1;32m      7[0m msg_count[38;5;241m=[39m[38;5;241m5[39m
[0;32m----> 8[0m client [38;5;241m=[39m [43mKSQLAPI[49m[43m([49m[43murl[49m[38;5;241;43m=[39;49m[38;5;124;43m'[39;49m[38;5;124;43mhttp://localhost:8088[39;49m[38;5;124;43m'[39;49m[43m,[49m[43m [49m[43mtimeout[49m[38;5;241;43m=[39;49m[38;5;241;43m60000[39;49m[43m)[49m

File [0;32m/opt/hostedtoolcache/Python/3.9.12/x64/lib/python3.9/site-packages/ksql/client.py:19[0m, in [0;36mKSQLAPI.__init__[0;34m(self, url, max_retries, check_version, **kwargs)[0m
[1;32m     17[0m [38;5;28mself[39m[38;5;241m.[39msa [38;5;241m=[39m SimplifiedAPI(url, max_retries[38;5;241m=[39mmax_retries, [38;5;241m*[39m[38;5;241m*[39mkwargs)
[1;32m     18[0m [38;5;28;01mif[39;00m check_version [38;5;129;01mis[39;00m [38;5;28;01mTrue[39;00m:
[0;32m---> 19[0m     [38;5;28;43mself[39;49m[38;5;241;43m.[39;49m[43mget_ksql_version[49m[43m([49m[43m)[49m

File [0;32m/opt/hostedtoolcache/Python/3.9.12/x64/lib/python3.9/site-packages/ksql/client.py:29[0m, in [0;36mKSQLAPI.get_ksql_version[0;34m(self)[0m
[1;32m     28[0m [38;5;28;01mdef[39;00m [38;5;21mget_ksql_version[39m([38;5;28mself[39m):
[0;32m---> 29[0m     r [38;5;241m=[39m [38;5;28;43mself[39;49m[38;5;241;43m.[39;49m[43msa[49m[38;5;241;43m.[39;49m[43mget_request[49m[43m([49m[38;5;28;43mself[39;49m[38;5;241;43m.[39;49m[43murl[49m[43m [49m[38;5;241;43m+[39;49m[43m [49m[38;5;124;43m"[39;49m[38;5;124;43m/info[39;49m[38;5;124;43m"[39;49m[43m)[49m
[1;32m     30[0m     [38;5;28;01mif[39;00m r[38;5;241m.[39mstatus_code [38;5;241m==[39m [38;5;241m200[39m:
[1;32m     31[0m         info [38;5;241m=[39m r[38;5;241m.[39mjson()[38;5;241m.[39mget([38;5;124m"[39m[38;5;124mKsqlServerInfo[39m[38;5;124m"[39m)

File [0;32m/opt/hostedtoolcache/Python/3.9.12/x64/lib/python3.9/site-packages/ksql/api.py:133[0m, in [0;36mBaseAPI.get_request[0;34m(self, endpoint)[0m
[1;32m    131[0m [38;5;28;01mdef[39;00m [38;5;21mget_request[39m([38;5;28mself[39m, endpoint):
[1;32m    132[0m     auth [38;5;241m=[39m ([38;5;28mself[39m[38;5;241m.[39mapi_key, [38;5;28mself[39m[38;5;241m.[39msecret) [38;5;28;01mif[39;00m [38;5;28mself[39m[38;5;241m.[39mapi_key [38;5;129;01mor[39;00m [38;5;28mself[39m[38;5;241m.[39msecret [38;5;28;01melse[39;00m [38;5;28;01mNone[39;00m
[0;32m--> 133[0m     [38;5;28;01mreturn[39;00m [43mrequests[49m[38;5;241;43m.[39;49m[43mget[49m[43m([49m[43mendpoint[49m[43m,[49m[43m [49m[43mheaders[49m[38;5;241;43m=[39;49m[38;5;28;43mself[39;49m[38;5;241;43m.[39;49m[43mheaders[49m[43m,[49m[43m [49m[43mauth[49m[38;5;241;43m=[39;49m[43mauth[49m[43m)[49m

File [0;32m/opt/hostedtoolcache/Python/3.9.12/x64/lib/python3.9/site-packages/requests/api.py:75[0m, in [0;36mget[0;34m(url, params, **kwargs)[0m
[1;32m     64[0m [38;5;28;01mdef[39;00m [38;5;21mget[39m(url, params[38;5;241m=[39m[38;5;28;01mNone[39;00m, [38;5;241m*[39m[38;5;241m*[39mkwargs):
[1;32m     65[0m     [38;5;124mr[39m[38;5;124;03m"""Sends a GET request.[39;00m
[1;32m     66[0m 
[1;32m     67[0m [38;5;124;03m    :param url: URL for the new :class:`Request` object.[39;00m
[0;32m   (...)[0m
[1;32m     72[0m [38;5;124;03m    :rtype: requests.Response[39;00m
[1;32m     73[0m [38;5;124;03m    """[39;00m
[0;32m---> 75[0m     [38;5;28;01mreturn[39;00m [43mrequest[49m[43m([49m[38;5;124;43m'[39;49m[38;5;124;43mget[39;49m[38;5;124;43m'[39;49m[43m,[49m[43m [49m[43murl[49m[43m,[49m[43m [49m[43mparams[49m[38;5;241;43m=[39;49m[43mparams[49m[43m,[49m[43m [49m[38;5;241;43m*[39;49m[38;5;241;43m*[39;49m[43mkwargs[49m[43m)[49m

File [0;32m/opt/hostedtoolcache/Python/3.9.12/x64/lib/python3.9/site-packages/requests/api.py:61[0m, in [0;36mrequest[0;34m(method, url, **kwargs)[0m
[1;32m     57[0m [38;5;66;03m# By using the 'with' statement we are sure the session is closed, thus we[39;00m
[1;32m     58[0m [38;5;66;03m# avoid leaving sockets open which can trigger a ResourceWarning in some[39;00m
[1;32m     59[0m [38;5;66;03m# cases, and look like a memory leak in others.[39;00m
[1;32m     60[0m [38;5;28;01mwith[39;00m sessions[38;5;241m.[39mSession() [38;5;28;01mas[39;00m session:
[0;32m---> 61[0m     [38;5;28;01mreturn[39;00m [43msession[49m[38;5;241;43m.[39;49m[43mrequest[49m[43m([49m[43mmethod[49m[38;5;241;43m=[39;49m[43mmethod[49m[43m,[49m[43m [49m[43murl[49m[38;5;241;43m=[39;49m[43murl[49m[43m,[49m[43m [49m[38;5;241;43m*[39;49m[38;5;241;43m*[39;49m[43mkwargs[49m[43m)[49m

File [0;32m/opt/hostedtoolcache/Python/3.9.12/x64/lib/python3.9/site-packages/requests/sessions.py:529[0m, in [0;36mSession.request[0;34m(self, method, url, params, data, headers, cookies, files, auth, timeout, allow_redirects, proxies, hooks, stream, verify, cert, json)[0m
[1;32m    524[0m send_kwargs [38;5;241m=[39m {
[1;32m    525[0m     [38;5;124m'[39m[38;5;124mtimeout[39m[38;5;124m'[39m: timeout,
[1;32m    526[0m     [38;5;124m'[39m[38;5;124mallow_redirects[39m[38;5;124m'[39m: allow_redirects,
[1;32m    527[0m }
[1;32m    528[0m send_kwargs[38;5;241m.[39mupdate(settings)
[0;32m--> 529[0m resp [38;5;241m=[39m [38;5;28;43mself[39;49m[38;5;241;43m.[39;49m[43msend[49m[43m([49m[43mprep[49m[43m,[49m[43m [49m[38;5;241;43m*[39;49m[38;5;241;43m*[39;49m[43msend_kwargs[49m[43m)[49m
[1;32m    531[0m [38;5;28;01mreturn[39;00m resp

File [0;32m/opt/hostedtoolcache/Python/3.9.12/x64/lib/python3.9/site-packages/requests/sessions.py:645[0m, in [0;36mSession.send[0;34m(self, request, **kwargs)[0m
[1;32m    642[0m start [38;5;241m=[39m preferred_clock()
[1;32m    644[0m [38;5;66;03m# Send the request[39;00m
[0;32m--> 645[0m r [38;5;241m=[39m [43madapter[49m[38;5;241;43m.[39;49m[43msend[49m[43m([49m[43mrequest[49m[43m,[49m[43m [49m[38;5;241;43m*[39;49m[38;5;241;43m*[39;49m[43mkwargs[49m[43m)[49m
[1;32m    647[0m [38;5;66;03m# Total elapsed time of the request (approximately)[39;00m
[1;32m    648[0m elapsed [38;5;241m=[39m preferred_clock() [38;5;241m-[39m start

File [0;32m/opt/hostedtoolcache/Python/3.9.12/x64/lib/python3.9/site-packages/requests/adapters.py:519[0m, in [0;36mHTTPAdapter.send[0;34m(self, request, stream, timeout, verify, cert, proxies)[0m
[1;32m    515[0m     [38;5;28;01mif[39;00m [38;5;28misinstance[39m(e[38;5;241m.[39mreason, _SSLError):
[1;32m    516[0m         [38;5;66;03m# This branch is for urllib3 v1.22 and later.[39;00m
[1;32m    517[0m         [38;5;28;01mraise[39;00m SSLError(e, request[38;5;241m=[39mrequest)
[0;32m--> 519[0m     [38;5;28;01mraise[39;00m [38;5;167;01mConnectionError[39;00m(e, request[38;5;241m=[39mrequest)
[1;32m    521[0m [38;5;28;01mexcept[39;00m ClosedPoolError [38;5;28;01mas[39;00m e:
[1;32m    522[0m     [38;5;28;01mraise[39;00m [38;5;167;01mConnectionError[39;00m(e, request[38;5;241m=[39mrequest)

[0;31mConnectionError[0m: HTTPConnectionPool(host='localhost', port=8088): Max retries exceeded with url: /info (Caused by NewConnectionError('<urllib3.connection.HTTPConnection object at 0x7f78e0a1a400>: Failed to establish a new connection: [Errno 111] Connection refused'))
ConnectionError: HTTPConnectionPool(host='localhost', port=8088): Max retries exceeded with url: /info (Caused by NewConnectionError('<urllib3.connection.HTTPConnection object at 0x7f78e0a1a400>: Failed to establish a new connection: [Errno 111] Connection refused'))

